<?xml version="1.0" ?>
<!-- =================================================================================== -->
<!-- |    This document was autogenerated by xacro from sim_robot.urdf.xacro           | -->
<!-- |    EDITING THIS FILE BY HAND IS NOT RECOMMENDED                                 | -->
<!-- =================================================================================== -->
<robot name="car">
  <!-- Materials -->
  <material name="CarBody">
    <color rgba="0.2 0.2 0.8 1.0"/>
    <!-- Metallic Blue -->
  </material>
  <material name="WheelMaterial">
    <color rgba="0.05 0.05 0.05 1.0"/>
    <!-- Dark Rubber -->
  </material>
  <!-- Base Footprint -->
  <link name="base_footprint"/>
  <joint name="base_footprint_joint" type="fixed">
    <parent link="base_footprint"/>
    <child link="base_link"/>
    <origin rpy="0 0 0" xyz="0 0 0.033"/>
  </joint>
  <!-- Base Link -->
  <link name="base_link">
    <visual>
      <origin rpy="0 0 0" xyz="0 0 0.05"/>
      <geometry>
        <box size="0.2 0.15 0.05"/>
      </geometry>
      <material name="CarBody"/>
    </visual>
    <collision>
      <origin rpy="0 0 0" xyz="0 0 0.025"/>
      <geometry>
        <box size="0.2 0.15 0.05"/>
      </geometry>
    </collision>
    <inertial>
      <mass value="0.3"/>
      <origin rpy="0 0 0" xyz="0 0 0.025"/>
      <inertia ixx="0.01" ixy="0" ixz="0" iyy="0.01" iyz="0" izz="0.01"/>
    </inertial>
  </link>
  <!-- Lidar -->
  <link name="lidar">
    <visual>
      <origin rpy="0 0 0" xyz="0 0 0"/>
      <geometry>
        <sphere radius="0.02"/>
      </geometry>
      <material name="LidarGlass"/>
    </visual>
    <collision>
      <origin rpy="0 0 0" xyz="0 0 0"/>
      <geometry>
        <sphere radius="0.02"/>
      </geometry>
    </collision>
    <inertial>
      <mass value="0.1"/>
      <origin rpy="0 0 0" xyz="0 0 0"/>
      <inertia ixx="0.000005" ixy="0" ixz="0" iyy="0.000005" iyz="0" izz="0.000005"/>
    </inertial>
  </link>
  <joint name="lidar_joint" type="fixed">
    <parent link="base_link"/>
    <child link="lidar"/>
    <origin rpy="0 0 0" xyz="0 0 0.07"/>
  </joint>
  <!-- Left Front Wheel -->
  <link name="left_front_wheel">
    <visual>
      <origin rpy="1.570795 0 0" xyz="0 0 0"/>
      <geometry>
        <cylinder length="0.02" radius="0.033"/>
      </geometry>
      <material name="WheelMaterial"/>
    </visual>
    <collision>
      <origin rpy="1.570795 0 0" xyz="0 0 0"/>
      <geometry>
        <cylinder length="0.02" radius="0.033"/>
      </geometry>
    </collision>
    <inertial>
      <mass value="0.3"/>
      <origin rpy="0 0 0" xyz="0 0 0"/>
      <inertia ixx="0.0001" ixy="0" ixz="0" iyy="0.0001" iyz="0" izz="0.0001"/>
    </inertial>
  </link>
  <joint name="left_front_wheel_joint" type="continuous">
    <parent link="base_link"/>
    <child link="left_front_wheel"/>
    <origin rpy="0 0 0" xyz="0.075 0.1 0.033"/>
    <axis xyz="0 1 0"/>
  </joint>
  <!-- Left Rear Wheel -->
  <link name="left_rear_wheel">
    <visual>
      <origin rpy="1.570795 0 0" xyz="0 0 0"/>
      <geometry>
        <cylinder length="0.02" radius="0.033"/>
      </geometry>
      <material name="WheelMaterial"/>
    </visual>
    <collision>
      <origin rpy="1.570795 0 0" xyz="0 0 0"/>
      <geometry>
        <cylinder length="0.02" radius="0.033"/>
      </geometry>
    </collision>
    <inertial>
      <mass value="0.3"/>
      <origin rpy="0 0 0" xyz="0 0 0"/>
      <inertia ixx="0.0001" ixy="0" ixz="0" iyy="0.0001" iyz="0" izz="0.0001"/>
    </inertial>
  </link>
  <joint name="left_rear_wheel_joint" type="continuous">
    <parent link="base_link"/>
    <child link="left_rear_wheel"/>
    <origin rpy="0 0 0" xyz="-0.075 0.1 0.033"/>
    <axis xyz="0 1 0"/>
  </joint>
  <!-- Right Front Wheel -->
  <link name="right_front_wheel">
    <visual>
      <origin rpy="1.570795 0 0" xyz="0 0 0"/>
      <geometry>
        <cylinder length="0.02" radius="0.033"/>
      </geometry>
      <material name="WheelMaterial"/>
    </visual>
    <collision>
      <origin rpy="1.570795 0 0" xyz="0 0 0"/>
      <geometry>
        <cylinder length="0.02" radius="0.033"/>
      </geometry>
    </collision>
    <inertial>
      <mass value="0.3"/>
      <origin rpy="0 0 0" xyz="0 0 0"/>
      <inertia ixx="0.0001" ixy="0" ixz="0" iyy="0.0001" iyz="0" izz="0.0001"/>
    </inertial>
  </link>
  <joint name="right_front_wheel_joint" type="continuous">
    <parent link="base_link"/>
    <child link="right_front_wheel"/>
    <origin rpy="0 0 0" xyz="0.075 -0.1 0.033"/>
    <axis xyz="0 1 0"/>
  </joint>
  <!-- Right Rear Wheel -->
  <link name="right_rear_wheel">
    <visual>
      <origin rpy="1.570795 0 0" xyz="0 0 0"/>
      <geometry>
        <cylinder length="0.02" radius="0.033"/>
      </geometry>
      <material name="WheelMaterial"/>
    </visual>
    <collision>
      <origin rpy="1.570795 0 0" xyz="0 0 0"/>
      <geometry>
        <cylinder length="0.02" radius="0.033"/>
      </geometry>
    </collision>
    <inertial>
      <mass value="0.3"/>
      <origin rpy="0 0 0" xyz="0 0 0"/>
      <inertia ixx="0.0001" ixy="0" ixz="0" iyy="0.0001" iyz="0" izz="0.0001"/>
    </inertial>
  </link>
  <joint name="right_rear_wheel_joint" type="continuous">
    <parent link="base_link"/>
    <child link="right_rear_wheel"/>
    <origin rpy="0 0 0" xyz="-0.075 -0.1 0.033"/>
    <axis xyz="0 1 0"/>
  </joint>
  <ros2_control name="GazeboSystem" type="system">
    <hardware>
      <plugin>gazebo_ros2_control/GazeboSystem</plugin>
    </hardware>
    <joint name="left_front_wheel_joint">
      <command_interface name="velocity">
        <param name="min">-500</param>
        <param name="max">500</param>
      </command_interface>
      <state_interface name="velocity"/>
      <state_interface name="position"/>
    </joint>
    <joint name="left_rear_wheel_joint">
      <command_interface name="velocity">
        <param name="min">-500</param>
        <param name="max">500</param>
      </command_interface>
      <state_interface name="velocity"/>
      <state_interface name="position"/>
    </joint>
    <joint name="right_front_wheel_joint">
      <command_interface name="velocity">
        <param name="min">-500</param>
        <param name="max">500</param>
      </command_interface>
      <state_interface name="velocity"/>
      <state_interface name="position"/>
    </joint>
    <joint name="right_rear_wheel_joint">
      <command_interface name="velocity">
        <param name="min">-500</param>
        <param name="max">500</param>
      </command_interface>
      <state_interface name="velocity"/>
      <state_interface name="position"/>
    </joint>
  </ros2_control>
  <gazebo>
    <plugin filename="libgazebo_ros2_control.so" name="gazebo_ros2_control">
      <robot_param>robot_description</robot_param>
      <robot_param_node>robot_state_publisher</robot_param_node>
      <parameters>/home/hmuegyi/Documents/robot_sim_ws/install/four_wheels_robot_description/share/four_wheels_robot_description/config/my_controllers.yaml</parameters>
      <odometry_frame>odom</odometry_frame>
      <robot_base_frame>base_footprint</robot_base_frame>
      <publish_odom>true</publish_odom>
      <publish_odom_tf>true</publish_odom_tf>
      <publish_wheel_tf>true</publish_wheel_tf>
    </plugin>
  </gazebo>
  <gazebo reference="imu_link">
    <gravity>true</gravity>
    <sensor name="imu_sensor" type="imu">
      <always_on>true</always_on>
      <update_rate>20</update_rate>
      <visualize>true</visualize>
      <topic>/imu</topic>
      <plugin filename="libgazebo_ros_imu_sensor.so" name="imu_plugin">
        <topicName>imu</topicName>
        <bodyName>imu_link</bodyName>
        <updateRateHZ>10.0</updateRateHZ>
        <gaussianNoise>0.0</gaussianNoise>
        <xyzOffset>0 0 0</xyzOffset>
        <rpyOffset>0 0 0</rpyOffset>
        <frameName>imu_link</frameName>
        <initialOrientationAsReference>false</initialOrientationAsReference>
      </plugin>
      <pose>0 0 0 0 0 0</pose>
    </sensor>
  </gazebo>
  <gazebo reference="lidar">
    <material>Gazebo/Red</material>
    <sensor name="laser" type="ray">
      <pose>0 0 0 0 0 0</pose>
      <visualize>true</visualize>
      <update_rate>10</update_rate>
      <ray>
        <scan>
          <horizontal>
            <samples>360</samples>
            <resolution>1</resolution>
            <min_angle>-2.3562</min_angle>
            <!-- -3.14 -->
            <max_angle>2.3562</max_angle>
            <!-- 3.14 -->
          </horizontal>
        </scan>
        <range>
          <min>0.05</min>
          <!-- 0.3 -->
          <max>12</max>
          <!-- 12 -->
          <resolution>0.01</resolution>
        </range>
      </ray>
      <plugin filename="libgazebo_ros_ray_sensor.so" name="laser_controller">
        <ros>
          <argument>~/out:=scan</argument>
        </ros>
        <output_type>sensor_msgs/LaserScan</output_type>
        <frame_name>lidar</frame_name>
      </plugin>
    </sensor>
  </gazebo>
  <!-- <xacro:include filename="hw_ros2_control.xacro" />  -->
  <!-- <xacro:include filename="gazebo_control.xacro" /> -->
  <!-- <xacro:include filename="camera.xacro" /> -->
  <!-- <xacro:include filename="camera3d.xacro" /> -->
</robot>
